Workbook

Sheet Übersicht_Vorkultur
A1: Wo | B1: (Alle)
A2: Lage | B2: (Alle)
A3: Pflanzort | B3: (Alle)
A5: Gruppe | B5: Katalog | C5: Pflanze | D5: Vorkultur | E5: Keimtemperatur C° | F5: Keimdauer Tage | G5: Saattiefe cm | H5: Direktsaat | I5: Ernährung | J5: AZ
A6: 0 | B6: Anzucht | C6: Baby div. | D6: 0 | E6: 0 | F6: 0 | G6: 0 | H6: 0 | I6: Erde
A7: 0 | B7: Lager | C7: Lagerfläche | D7: 0 | E7: 0 | F7: 0 | G7: 0 | H7: 0 | I7: Erde | J7: 12
A8: 0 | B8: Lager | C8: Lagerfläche | D8: 0 | E8: 0 | F8: 0 | G8: 0 | H8: 0 | I8: trocken
A9: 0 | B9: Elektro | C9: Elektro | D9: 0 | E9: 0 | F9: 0 | G9: 0 | H9: 0 | I9: trocken
A10: 0 | B10: Blumen | C10: Sonnenhut | D10: 0 | E10: 0 | F10: 0 | G10: 0 | H10: 0 | I10: Erde | J10: 2
A11: 0 Ergebnis | J11: 14
A12: Blatt | B12: 5 | C12: Wintermarie | D12: 01.02.-28.02. | E12: 10-15 | F12: 5-7 | G12: Licht | H12: 15.07.-31.08. | I12: Erde | J12: 2
A13: Blatt | B13: 10 | C13: Schnittsalat Asia Oriental Mix | D13: 01.01.-30.04. | E13: 10-20 | F13: 8-15 | G13: 1-2 | H13: 15.07.-01.10. | I13: Erde | J13: 27
A14: Blatt | B14: 11 | C14: Schnittsalat Misticanza | D14: 01.01.-30.04. | E14: 10-15 | F14: 7-14 | G14: 1-2 | H14: 01.02.-01.09. | I14: Erde | J14: 27
A15: Blatt | B15: 12 | C15: Pflücksalat Red Salat Bowl | D15: 01.02. | E15: 15 | F15: 0 | G15: 0,2 | H15: 01.03.-30.09. | I15: Erde | J15: 6
A16: Blatt | B16: 13 | C16: Spinat Matador | D16: 01.01.-30.03. | E16: 10-15 | F16: 7-14 | G16: 3 | H16: 01.03.-01.09. | I16: Erde | J16: 2
A17: Blatt | B17: 19 | C17: Salat div. | D17: 01.02. | E17: 15 | F17: 0 | G17: 0,2 | H17: 01.03.-30.09. | I17: Erde | J17: 4
A18: Blatt | B18: 19 | C18: Salat div. | D18: 01.02. | E18: 15 | F18: 0 | G18: 0,2 | H18: 01.03.-30.09. | I18: trocken
A19: Blatt | B19: 20 | C19: Pflücksalat weiß | D19: 01.02. | E19: 15 | F19: 0 | G19: 0,2 | H19: 01.03.-30.09. | I19: Erde | J19: 6
A20: Blatt Ergebnis | J20: 74
A21: Frucht | B21: 1 | C21: Fleischparadeiser Rotes Herz | D21: 15.03-15.04 | E21: 20-25 | F21: 8-10 | G21: Licht | H21: nein | I21: Erde | J21: 4
A22: Frucht | B22: 2 | C22: Salatparadeiser Quedlinburger Frühe Liebe | D22: 15.03-15.04 | E22: 20-25 | F22: 8-10 | G22: Licht | H22: nein | I22: Erde | J22: 4
A23: Frucht | B23: 6 | C23: Cocktailparadeiser Golden Perfection | D23: 15.03-15.04 | E23: 20-25 | F23: 8-10 | G23: Licht | H23: nein | I23: Erde | J23: 3
A24: Frucht | B24: 9 | C24: Cocktailparadeiser Red Currant | D24: 15.03-15.04 | E24: 20-25 | F24: 8-10 | G24: Licht | H24: nein | I24: Erde | J24: 3
A25: Frucht | B25: 14 | C25: Chili Lemon Drop | D25: 01.03. | E25: 25-30 | F25: 10-14 | G25: 1 | H25: nein | I25: Erde | J25: 2
A26: Frucht | B26: 16 | C26: Zuckermelone | D26: 01.04. | E26: 24 | F26: 7-14 | G26: 0 | H26: 01.05. | I26: Erde | J26: 2
A27: Frucht | B27: 17 | C27: Chili spitz rot | D27: 01.03. | E27: 25-30 | F27: 10-14 | G27: 1 | H27: nein | I27: Erde | J27: 2
A28: Frucht | B28: 18 | C28: Paprika spitz rot | D28: 01.02.-15.04. | E28: 22-25 | F28: 10-14 | G28: 0,5-1 | H28: nein | I28: Erde | J28: 2
A29: Frucht | B29: 23 | C29: Aubergine Melanzani | D29: 01.02. | E29: 20-25 | F29: 7-21 | G29: 1-2 | H29: nein | I29: Erde | J29: 2
A30: Frucht | B30: 27 | C30: Gurke Melothria | D30: 15.04.-30.04. | E30: 25-28 | F30: 5-8 | G30: 2-3 | H30: 01.05.-30.06. | I30: Erde | J30: 2
A31: Frucht | B31: 28 | C31: Gurke Pappelchen | D31: 15.04.-30.04. | E31: 25-28 | F31: 5-8 | G31: 2-3 | H31: 01.05.-30.06. | I31: Erde | J31: 1
A32: Frucht | B32: 29 | C32: Cocktailparadeiser Gelbe Johannisbeere | D32: 01.02-31.03. | E32: 20-22 | F32: 8-10 | G32: Licht | H32: nein | I32: Erde | J32: 3
A33: Frucht | B33: 31 | C33: Zucchini Largo Blanco Serpiente | D33: 15.04. | E33: 18-22 | F33: 7-14 | G33: 2-3 | H33: 15.05.-15.06. | I33: Erde | J33: 2
A34: Frucht | B34: 40 | C34: Paprika Neusiedler Ideal rot | D34: 01.02.-15.04. | E34: 20-25 | F34: 14-21 | G34: 0,5-1 | H34: 15.05. | I34: Erde | J34: 2
A35: Frucht | B35: 48 | C35: Salatparadeiser gestreift SPAR | D35: 15.03-15.04. | E35: 20-25 | F35: 8-10 | G35: Licht | H35: nein | I35: Erde | J35: 2
A36: Frucht | B36: 51 | C36: Chili Diavoletto | D36: 15.02.-15.03. | E36: 20-25 | F36: 10-14 | G36: 1 | H36: nein | I36: Erde | J36: 4
A37: Frucht | B37: 50 | C37: Paprika Snack Hamik | D37: 15.01.-31.03. | E37: 20-25 | F37: 14-21 | G37: 0,5-1 | H37: 15.05.-15.06. | I37: Erde | J37: 4
A38: Frucht | B38: 49 | C38: Paradeiser Ochsenherz Tschernij Prinz | D38: 01.02-31.03. | E38: 20-25 | F38: 8-10 | G38: 0,5-1 | H38: 15.05-31.05. | I38: Erde | J38: 3
A39: Frucht Ergebnis | J39: 47
A40: Hülse | B40: 7 | C40: Zuckererbse Ambrosia | D40: 01.03.-31.05. | E40: 10-20 | F40: 8-14 | G40: 3 | H40: 01.03.-31.05. | I40: Erde | J40: 10
A41: Hülse | B41: 8 | C41: Knackerbse Spring Blush | D41: 01.03.-31.05. | E41: 10-20 | F41: 8-14 | G41: 3 | H41: 01.03.-31.05. | I41: Erde | J41: 10
...

Sheet Übersicht_Auspflanzung
A1: Nummer | B1: Pflanzort | C1: Kennzahl | D1: Gefäß | E1: Ernährung | F1: Katalog | G1: AZ | H1: Pflanze | I1: Keimtemperatur C° | J1: Saattiefe cm | K1: Aussetzen | L1: Direktsaat
A2: 1 | B2: Niederregal | C2: 1OA | D2: Stahl 20 | E2: Erde | F2: 17 | G2: 2 | H2: Chili spitz rot | I2: 25-30 | J2: 1 | K2: 01.05. | L2: nein
A3: 1 | B3: Niederregal | C3: 1OA | D3: Stahl 20 | E3: Erde | F3: 51 | G3: 2 | H3: Chili Diavoletto | I3: 20-25 | J3: 1 | K3: 15.04.-30.04. | L3: nein
A4: 1 | B4: Niederregal | C4: 1OB | D4: Stahl 20 | E4: Erde | F4: 40 | G4: 2 | H4: Paprika Neusiedler Ideal rot | I4: 20-25 | J4: 0,5-1 | K4: 01.04.-01.06. | L4: 15.05.
A5: 1 | B5: Niederregal | C5: 1OB | D5: Stahl 20 | E5: Erde | F5: 50 | G5: 2 | H5: Paprika Snack Hamik | I5: 20-25 | J5: 0,5-1 | K5: 15.04.-30.04. | L5: 15.05.-15.06.
A6: 1 | B6: Niederregal | C6: 1OC | D6: Stahl 30 | E6: Erde | F6: 7 | G6: 10 | H6: Zuckererbse Ambrosia | I6: 10-20 | J6: 3 | K6: 0 | L6: 01.03.-31.05.
A7: 1 | B7: Niederregal | C7: 1UA | D7: Stahl 30 | E7: Erde | F7: 1 | G7: 1 | H7: Fleischparadeiser Rotes Herz | I7: 20-25 | J7: Licht | K7: 15.05-31.05. | L7: nein
A8: 1 | B8: Niederregal | C8: 1UA | D8: Stahl 30 | E8: Erde | F8: 3 | G8: 1 | H8: Basilikum Genoveser | I8: 18-22 | J8: Licht | K8: 01.05. | L8: 31.05.-31.07.
A9: 1 | B9: Niederregal | C9: 1UA | D9: Stahl 30 | E9: Erde | F9: 6 | G9: 1 | H9: Cocktailparadeiser Golden Perfection | I9: 20-25 | J9: Licht | K9: 15.05-31.05. | L9: nein
A10: 1 | B10: Niederregal | C10: 1UB | D10: Stahl 20 | E10: Erde | F10: 4 | G10: 3 | H10: Kohlrabi Superschmelz | I10: 16-20 | J10: 2 | K10: 01.04. | L10: 01.04.-31.05.
A11: 1 | B11: Niederregal | C11: 1UC | D11: Stahl 20 | E11: Erde | F11: 41 | G11: 10 | H11: Zwiebel Mix | I11: 10-20 | J11: 1-3 | K11: 01.04. | L11: 01.03.-30.04.
A12: 1 | B12: Niederregal | C12: 1UC | D12: Stahl 20 | E12: Erde | F12: 42 | G12: 2 | H12: Schnittlauch | I12: 18-20 | J12: 0,5-1 | K12: 01.04. | L12: 01.03.-30.04.
A13: 1 Ergebnis
A14: 2 | B14: Niederregal | C14: 2OA | D14: Topf | E14: Erde | F14: 16 | G14: 1 | H14: Zuckermelone | I14: 24 | J14: 0 | K14: 01.05. | L14: 01.05.
A15: 2 | B15: Niederregal | C15: 2OB | D15: Platte | E15: Erde | F15: Anzucht | G15: (Leer) | H15: Baby div. | I15: 0 | J15: 0 | K15: 0 | L15: 0
A16: 2 | B16: Niederregal | C16: 2OC | D16: Platte | E16: Erde | F16: Anzucht | G16: (Leer) | H16: Baby div. | I16: 0 | J16: 0 | K16: 0 | L16: 0
A17: 2 | B17: Niederregal | C17: 2UA | D17: Stahl 30 | E17: Erde | F17: 2 | G17: 1 | H17: Salatparadeiser Quedlinburger Frühe Liebe | I17: 20-25 | J17: Licht | K17: 15.05-31.05. | L17: nein
A18: 2 | B18: Niederregal | C18: 2UA | D18: Stahl 30 | E18: Erde | F18: 49 | G18: 1 | H18: Paradeiser Ochsenherz Tschernij Prinz | I18: 20-25 | J18: 0,5-1 | K18: 15.04.-15.05. | L18: 15.05-31.05.
A19: 2 | B19: Niederregal | C19: 2UB | D19: Platte | E19: trocken | F19: Lager | G19: (Leer) | H19: Lagerfläche | I19: 0 | J19: 0 | K19: 0 | L19: 0
A20: 2 | B20: Niederregal | C20: 2UC | D20: Platte | E20: trocken | F20: Lager | G20: (Leer) | H20: Lagerfläche | I20: 0 | J20: 0 | K20: 0 | L20: 0
A21: 2 Ergebnis
A22: 3 | B22: Niederregal | C22: 3OA | D22: Stahl 20 | E22: Erde | F22: 14 | G22: 2 | H22: Chili Lemon Drop | I22: 25-30 | J22: 1 | K22: 01.05. | L22: nein
A23: 3 | B23: Niederregal | C23: 3OA | D23: Stahl 20 | E23: Erde | F23: 51 | G23: 2 | H23: Chili Diavoletto | I23: 20-25 | J23: 1 | K23: 15.04.-30.04. | L23: nein
A24: 3 | B24: Niederregal | C24: 3OB | D24: Stahl 20 | E24: Erde | F24: 18 | G24: 2 | H24: Paprika spitz rot | I24: 22-25 | J24: 0,5-1 | K24: 01.04.-01.06. | L24: nein
A25: 3 | B25: Niederregal | C25: 3OB | D25: Stahl 20 | E25: Erde | F25: 50 | G25: 2 | H25: Paprika Snack Hamik | I25: 20-25 | J25: 0,5-1 | K25: 15.04.-30.04. | L25: 15.05.-15.06.
A26: 3 | B26: Niederregal | C26: 3OC | D26: Stahl 30 | E26: Erde | F26: 8 | G26: 10 | H26: Knackerbse Spring Blush | I26: 10-20 | J26: 3 | K26: 0 | L26: 01.03.-31.05.
A27: 3 | B27: Niederregal | C27: 3UA | D27: Stahl 30 | E27: Erde | F27: 1 | G27: 1 | H27: Fleischparadeiser Rotes Herz | I27: 20-25 | J27: Licht | K27: 15.05-31.05. | L27: nein
A28: 3 | B28: Niederregal | C28: 3UA | D28: Stahl 30 | E28: Erde | F28: 3 | G28: 1 | H28: Basilikum Genoveser | I28: 18-22 | J28: Licht | K28: 01.05. | L28: 31.05.-31.07.
A29: 3 | B29: Niederregal | C29: 3UA | D29: Stahl 30 | E29: Erde | F29: 48 | G29: 1 | H29: Salatparadeiser gestreift SPAR | I29: 20-25 | J29: Licht | K29: 15.05-31.05. | L29: nein
A30: 3 | B30: Niederregal | C30: 3UB | D30: Stahl 20 | E30: Erde | F30: 4 | G30: 3 | H30: Kohlrabi Superschmelz | I30: 16-20 | J30: 2 | K30: 01.04. | L30: 01.04.-31.05.
A31: 3 | B31: Niederregal | C31: 3UC | D31: Platte | E31: Erde | F31: 10 | G31: 25 | H31: Schnittsalat Asia Oriental Mix | I31: 10-20 | J31: 1-2 | K31: 01.02. | L31: 15.07.-01.10.
A32: 3 | B32: Niederregal | C32: 3UC | D32: Platte | E32: Erde | F32: 11 | G32: 25 | H32: Schnittsalat Misticanza | I32: 10-15 | J32: 1-2 | K32: 01.02. | L32: 01.02.-01.09.
A33: 3 Ergebnis
A34: 4 | B34: Niederregal | C34: 4OA | D34: Stahl 30 | E34: Erde | F34: 23 | G34: 2 | H34: Aubergine Melanzani | I34: 20-25 | J34: 1-2 | K34: 15.05. | L34: nein
A35: 4 | B35: Niederregal | C35: 4OB | D35: Stahl 20 | E35: Erde | F35: 20 | G35: 6 | H35: Pflücksalat weiß | I35: 15 | J35: 0,2 | K35: 0 | L35: 01.03.-30.09.
A36: 4 | B36: Niederregal | C36: 4OC | D36: Stahl 20 | E36: Erde | F36: 12 | G36: 6 | H36: Pflücksalat Red Salat Bowl | I36: 15 | J36: 0,2 | K36: 0 | L36: 01.03.-30.09.
A37: 4 | B37: Niederregal | C37: 4UA | D37: Stahl 30 | E37: Erde | F37: 2 | G37: 1 | H37: Salatparadeiser Quedlinburger Frühe Liebe | I37: 20-25 | J37: Licht | K37: 15.05-31.05. | L37: nein
A38: 4 | B38: Niederregal | C38: 4UA | D38: Stahl 30 | E38: Erde | F38: 49 | G38: 1 | H38: Paradeiser Ochsenherz Tschernij Prinz | I38: 20-25 | J38: 0,5-1 | K38: 15.04.-15.05. | L38: 15.05-31.05.
A39: 4 | B39: Niederregal | C39: 4UB | D39: Platte | E39: Erde | F39: Lager | G39: (Leer) | H39: Lagerfläche | I39: 0 | J39: 0 | K39: 0 | L39: 0
A40: 4 | B40: Niederregal | C40: 4UC | D40: Stahl 30 | E40: Erde | F40: 2 | G40: 1 | H40: Salatparadeiser Quedlinburger Frühe Liebe | I40: 20-25 | J40: Licht | K40: 15.05-31.05. | L40: nein
...

Sheet Bepflanzungsschema
A1: Kennzahl | B1: Wo | C1: Lage | D1: Licht | E1: Pflanzort | F1: Nummer | G1: Höhe | H1: Platz | I1: Gefäß | J1: Pflanzhilfe | K1: Ernährung | L1: Anzahl Pflanzen | M1: Katalog | N1: Pflanze | O1: Vorkultur | P1: Keimtemperatur C° | Q1: Keimdauer Tage | R1: Saattiefe cm | S1: Aussetzen | T1: Direktsaat | U1: Abstände Pflanze cm | V1: Abstände Reihe cm | W1: Ernte Start | X1: Wuchs | Y1: Samen | Z1: Pflanzpartner | AA1: Beipflanze | AB1: Pflanzgegner | AC1: Anspruch Pflege Pflanze | AD1: Details und Beschreibung | AE1: Kommentar | AF1: Gruppe
A2: 1OA | B2: Glashaus | C2: Norden/Mauer | D2: Sonne | E2: Niederregal | F2: 1 | G2: oben | H2: A | I2: Stahl 20 | J2: nein | K2: Erde | L2: 1 | M2: 17 | N2: =VLOOKUP($M2,Pflanzenkatalog!$A$2:$AB$632,2,FALSE) -> Chili spitz rot | O2: =VLOOKUP($M2,Pflanzenkatalog!$A$2:$AB$632,3,FALSE) -> 01.03. | P2: =VLOOKUP($M2,Pflanzenkatalog!$A$2:$AB$632,4,FALSE) -> 25-30 | Q2: =VLOOKUP($M2,Pflanzenkatalog!$A$2:$AB$632,5,FALSE) -> 10-14 | R2: =VLOOKUP($M2,Pflanzenkatalog!$A$2:$AB$632,6,FALSE) -> 1 | S2: =VLOOKUP($M2,Pflanzenkatalog!$A$2:$AB$632,7,FALSE) -> 01.05. | T2: =VLOOKUP($M2,Pflanzenkatalog!$A$2:$AB$632,8,FALSE) -> nein | U2: =VLOOKUP($M2,Pflanzenkatalog!$A$2:$AB$632,9,FALSE) -> 40 | V2: =VLOOKUP($M2,Pflanzenkatalog!$A$2:$AB$632,10,FALSE) -> 40 | W2: =VLOOKUP($M2,Pflanzenkatalog!$A$2:$AB$632,11,FALSE) -> August | X2: =VLOOKUP($M2,Pflanzenkatalog!$A$2:$AB$632,12,FALSE) -> 50-80 cm | Y2: =VLOOKUP($M2,Pflanzenkatalog!$A$2:$AB$632,13,FALSE) -> SPAR Bio | Z2: =VLOOKUP($M2,Pflanzenkatalog!$A$2:$AB$632,14,FALSE) -> 0 | AA2: =VLOOKUP($M2,Pflanzenkatalog!$A$2:$AB$632,15,FALSE) -> 0 | AB2: =VLOOKUP($M2,Pflanzenkatalog!$A$2:$AB$632,16,FALSE) -> 0 | AC2: =VLOOKUP($M2,Pflanzenkatalog!$A$2:$AB$632,17,FALSE) -> 0 | AD2: =VLOOKUP($M2,Pflanzenkatalog!$A$2:$AB$632,18,FALSE) -> 0 | AE2: =VLOOKUP($M2,Pflanzenkatalog!$A$2:$AB$632,19,FALSE) -> 0 | AF2: =VLOOKUP($M2,Pflanzenkatalog!$A$2:$AB$632,20,FALSE) -> Frucht
A3: 1OA | B3: Glashaus | C3: Norden/Mauer | D3: Sonne | E3: Niederregal | F3: 1 | G3: oben | H3: A | I3: Stahl 20 | J3: nein | K3: Erde | L3: 1 | M3: 51 | N3: =VLOOKUP($M3,Pflanzenkatalog!$A$2:$AB$632,2,FALSE) -> Chili Diavoletto | O3: =VLOOKUP($M3,Pflanzenkatalog!$A$2:$AB$632,3,FALSE) -> 15.02.-15.03. | P3: =VLOOKUP($M3,Pflanzenkatalog!$A$2:$AB$632,4,FALSE) -> 20-25 | Q3: =VLOOKUP($M3,Pflanzenkatalog!$A$2:$AB$632,5,FALSE) -> 10-14 | R3: =VLOOKUP($M3,Pflanzenkatalog!$A$2:$AB$632,6,FALSE) -> 1 | S3: =VLOOKUP($M3,Pflanzenkatalog!$A$2:$AB$632,7,FALSE) -> 15.04.-30.04. | T3: =VLOOKUP($M3,Pflanzenkatalog!$A$2:$AB$632,8,FALSE) -> nein | U3: =VLOOKUP($M3,Pflanzenkatalog!$A$2:$AB$632,9,FALSE) -> 50 | V3: =VLOOKUP($M3,Pflanzenkatalog!$A$2:$AB$632,10,FALSE) -> 70 | W3: =VLOOKUP($M3,Pflanzenkatalog!$A$2:$AB$632,11,FALSE) -> Juli | X3: =VLOOKUP($M3,Pflanzenkatalog!$A$2:$AB$632,12,FALSE) -> 50-80 cm | Y3: =VLOOKUP($M3,Pflanzenkatalog!$A$2:$AB$632,13,FALSE) -> REINSAAT | Z3: =VLOOKUP($M3,Pflanzenkatalog!$A$2:$AB$632,14,FALSE) -> Rucola, Radieschen, Pertersilie, Basilikum | AA3: =VLOOKUP($M3,Pflanzenkatalog!$A$2:$AB$632,15,FALSE) -> 0 | AB3: =VLOOKUP($M3,Pflanzenkatalog!$A$2:$AB$632,16,FALSE) -> 0 | AC3: =VLOOKUP($M3,Pflanzenkatalog!$A$2:$AB$632,17,FALSE) -> mehrjährig! Jungpflanzen wachsen langsam, vor Frost schützen, langsam abhärten, feuchtes, lockeres und nährstoffreichen Substrat, Boden im Idealfall einen neutralen bis leicht sauren pH-Wert, mit Kompost düngen | AD3: =VLOOKUP($M3,Pflanzenkatalog!$A$2:$AB$632,18,FALSE) -> Züchtung ReinSaat. Dekorativer, langgestreckter, fleischiger Chili mit attraktiven lilafarbenen Blüten, Stielen, Kelchen und Blattadern. Die Früchte reifen von lila auf goldbraun zu orangerot ab. Gut geeignet zum Frischverzehr, in Salsas oder zum Einlegen. Für Gewächshaus und geschützte Freilandlagen. Schärfegrad 6 – 7 | AE3: =VLOOKUP($M3,Pflanzenkatalog!$A$2:$AB$632,19,FALSE) -> 0 | AF3: =VLOOKUP($M3,Pflanzenkatalog!$A$2:$AB$632,20,FALSE) -> Frucht
A4: 1OB | B4: Glashaus | C4: Norden/Mauer | D4: Sonne | E4: Niederregal | F4: 1 | G4: oben | H4: B | I4: Stahl 20 | J4: nein | K4: Erde | L4: 1 | M4: 40 | N4: =VLOOKUP($M4,Pflanzenkatalog!$A$2:$AB$632,2,FALSE) -> Paprika Neusiedler Ideal rot | O4: =VLOOKUP($M4,Pflanzenkatalog!$A$2:$AB$632,3,FALSE) -> 01.02.-15.04. | P4: =VLOOKUP($M4,Pflanzenkatalog!$A$2:$AB$632,4,FALSE) -> 20-25 | Q4: =VLOOKUP($M4,Pflanzenkatalog!$A$2:$AB$632,5,FALSE) -> 14-21 | R4: =VLOOKUP($M4,Pflanzenkatalog!$A$2:$AB$632,6,FALSE) -> 0,5-1 | S4: =VLOOKUP($M4,Pflanzenkatalog!$A$2:$AB$632,7,FALSE) -> 01.04.-01.06. | T4: =VLOOKUP($M4,Pflanzenkatalog!$A$2:$AB$632,8,FALSE) -> 15.05. | U4: =VLOOKUP($M4,Pflanzenkatalog!$A$2:$AB$632,9,FALSE) -> 50 | V4: =VLOOKUP($M4,Pflanzenkatalog!$A$2:$AB$632,10,FALSE) -> 70 | W4: =VLOOKUP($M4,Pflanzenkatalog!$A$2:$AB$632,11,FALSE) -> Juli | X4: =VLOOKUP($M4,Pflanzenkatalog!$A$2:$AB$632,12,FALSE) -> 0 | Y4: =VLOOKUP($M4,Pflanzenkatalog!$A$2:$AB$632,13,FALSE) -> KIEPENKERL | Z4: =VLOOKUP($M4,Pflanzenkatalog!$A$2:$AB$632,14,FALSE) -> Salat | AA4: =VLOOKUP($M4,Pflanzenkatalog!$A$2:$AB$632,15,FALSE) -> Tagetes gegen Nematoden, Viren und weiße Fliege | AB4: =VLOOKUP($M4,Pflanzenkatalog!$A$2:$AB$632,16,FALSE) -> 0 | AC4: =VLOOKUP($M4,Pflanzenkatalog!$A$2:$AB$632,17,FALSE) -> Neusiedler Ideal' liefert hohe Erträge in der Ernteperiode von Mitte Juli bis Oktober. Eine Direktaussaat ins Freiland kann ab Mitte Mai erfolgen. Hier kommt es auf einen sonnigen, warmen und windgeschützten Standort an. Wer eher aussäen möchte, kann mit der Vorkultur im Haus ab Februar starten. Für den Gewächshausanbau ist die Sorte ebenfalls geeignet. | AD4: =VLOOKUP($M4,Pflanzenkatalog!$A$2:$AB$632,18,FALSE) -> Bei der Paprika 'Neusiedler Ideal' handelt es sich um eine leckere Speisepaprika mit blockigen Früchten, welche von Grün nach Rot abreifen. Sie können sowohl im grünen als auch im roten Stadium geerntet werden, wobei die voll abgereiften roten Paprika süßer im Geschmack sind. Bezüglich ihrer Inhaltsstoffe unterscheiden sie sich allerdings nicht. Die grünen und roten Früchte sind gleichermaßen gesund, da sie vor allem wichtige Vitamine enthalten, beispielsweise jede Menge Vitamin C. Voll ausgefärbte Früchte haben den höchsten Vitamin C-Gehalt. | AE4: =VLOOKUP($M4,Pflanzenkatalog!$A$2:$AB$632,19,FALSE) -> 0 | AF4: =VLOOKUP($M4,Pflanzenkatalog!$A$2:$AB$632,20,FALSE) -> Frucht
A5: 1OB | B5: Glashaus | C5: Norden/Mauer | D5: Sonne | E5: Niederregal | F5: 1 | G5: oben | H5: B | I5: Stahl 20 | J5: nein | K5: Erde | L5: 1 | M5: 50 | N5: =VLOOKUP($M5,Pflanzenkatalog!$A$2:$AB$632,2,FALSE) -> Paprika Snack Hamik | O5: =VLOOKUP($M5,Pflanzenkatalog!$A$2:$AB$632,3,FALSE) -> 15.01.-31.03. | P5: =VLOOKUP($M5,Pflanzenkatalog!$A$2:$AB$632,4,FALSE) -> 20-25 | Q5: =VLOOKUP($M5,Pflanzenkatalog!$A$2:$AB$632,5,FALSE) -> 14-21 | R5: =VLOOKUP($M5,Pflanzenkatalog!$A$2:$AB$632,6,FALSE) -> 0,5-1 | S5: =VLOOKUP($M5,Pflanzenkatalog!$A$2:$AB$632,7,FALSE) -> 15.04.-30.04. | T5: =VLOOKUP($M5,Pflanzenkatalog!$A$2:$AB$632,8,FALSE) -> 15.05.-15.06. | U5: =VLOOKUP($M5,Pflanzenkatalog!$A$2:$AB$632,9,FALSE) -> 50 | V5: =VLOOKUP($M5,Pflanzenkatalog!$A$2:$AB$632,10,FALSE) -> 70 | W5: =VLOOKUP($M5,Pflanzenkatalog!$A$2:$AB$632,11,FALSE) -> Juli | X5: =VLOOKUP($M5,Pflanzenkatalog!$A$2:$AB$632,12,FALSE) -> 20-50 cm | Y5: =VLOOKUP($M5,Pflanzenkatalog!$A$2:$AB$632,13,FALSE) -> REINSAAT | Z5: =VLOOKUP($M5,Pflanzenkatalog!$A$2:$AB$632,14,FALSE) -> Salat | AA5: =VLOOKUP($M5,Pflanzenkatalog!$A$2:$AB$632,15,FALSE) -> Tagetes gegen Nematoden, Viren und weiße Fliege | AB5: =VLOOKUP($M5,Pflanzenkatalog!$A$2:$AB$632,16,FALSE) -> 0 | AC5: =VLOOKUP($M5,Pflanzenkatalog!$A$2:$AB$632,17,FALSE) -> 0 | AD5: =VLOOKUP($M5,Pflanzenkatalog!$A$2:$AB$632,18,FALSE) -> 0 | AE5: =VLOOKUP($M5,Pflanzenkatalog!$A$2:$AB$632,19,FALSE) -> 0 | AF5: =VLOOKUP($M5,Pflanzenkatalog!$A$2:$AB$632,20,FALSE) -> Frucht
A6: 1OC | B6: Glashaus | C6: Norden/Mauer | D6: Sonne | E6: Niederregal | F6: 1 | G6: oben | H6: C | I6: Stahl 30 | J6: Gitter | K6: Erde | L6: 1 | M6: 18 | N6: =VLOOKUP($M6,Pflanzenkatalog!$A$2:$AB$632,2,FALSE) -> Paprika spitz rot | O6: =VLOOKUP($M6,Pflanzenkatalog!$A$2:$AB$632,3,FALSE) -> 01.02.-15.04. | P6: =VLOOKUP($M6,Pflanzenkatalog!$A$2:$AB$632,4,FALSE) -> 22-25 | Q6: =VLOOKUP($M6,Pflanzenkatalog!$A$2:$AB$632,5,FALSE) -> 10-14 | R6: =VLOOKUP($M6,Pflanzenkatalog!$A$2:$AB$632,6,FALSE) -> 0,5-1 | S6: =VLOOKUP($M6,Pflanzenkatalog!$A$2:$AB$632,7,FALSE) -> 01.04.-01.06. | T6: =VLOOKUP($M6,Pflanzenkatalog!$A$2:$AB$632,8,FALSE) -> nein | U6: =VLOOKUP($M6,Pflanzenkatalog!$A$2:$AB$632,9,FALSE) -> 60 | V6: =VLOOKUP($M6,Pflanzenkatalog!$A$2:$AB$632,10,FALSE) -> 80 | W6: =VLOOKUP($M6,Pflanzenkatalog!$A$2:$AB$632,11,FALSE) -> Juli | X6: =VLOOKUP($M6,Pflanzenkatalog!$A$2:$AB$632,12,FALSE) -> 50-80 cm | Y6: =VLOOKUP($M6,Pflanzenkatalog!$A$2:$AB$632,13,FALSE) -> SPAR Bio | Z6: =VLOOKUP($M6,Pflanzenkatalog!$A$2:$AB$632,14,FALSE) -> 0 | AA6: =VLOOKUP($M6,Pflanzenkatalog!$A$2:$AB$632,15,FALSE) -> 0 | AB6: =VLOOKUP($M6,Pflanzenkatalog!$A$2:$AB$632,16,FALSE) -> 0 | AC6: =VLOOKUP($M6,Pflanzenkatalog!$A$2:$AB$632,17,FALSE) -> 0 | AD6: =VLOOKUP($M6,Pflanzenkatalog!$A$2:$AB$632,18,FALSE) -> 0 | AE6: =VLOOKUP($M6,Pflanzenkatalog!$A$2:$AB$632,19,FALSE) -> 0 | AF6: =VLOOKUP($M6,Pflanzenkatalog!$A$2:$AB$632,20,FALSE) -> Frucht
A7: 1OC | B7: Glashaus | C7: Norden/Mauer | D7: Sonne | E7: Niederregal | F7: 1 | G7: oben | H7: C | I7: Stahl 30 | J7: Gitter | K7: Erde | L7: 1 | M7: 18 | N7: =VLOOKUP($M7,Pflanzenkatalog!$A$2:$AB$632,2,FALSE) -> Paprika spitz rot | O7: =VLOOKUP($M7,Pflanzenkatalog!$A$2:$AB$632,3,FALSE) -> 01.02.-15.04. | P7: =VLOOKUP($M7,Pflanzenkatalog!$A$2:$AB$632,4,FALSE) -> 22-25 | Q7: =VLOOKUP($M7,Pflanzenkatalog!$A$2:$AB$632,5,FALSE) -> 10-14 | R7: =VLOOKUP($M7,Pflanzenkatalog!$A$2:$AB$632,6,FALSE) -> 0,5-1 | S7: =VLOOKUP($M7,Pflanzenkatalog!$A$2:$AB$632,7,FALSE) -> 01.04.-01.06. | T7: =VLOOKUP($M7,Pflanzenkatalog!$A$2:$AB$632,8,FALSE) -> nein | U7: =VLOOKUP($M7,Pflanzenkatalog!$A$2:$AB$632,9,FALSE) -> 60 | V7: =VLOOKUP($M7,Pflanzenkatalog!$A$2:$AB$632,10,FALSE) -> 80 | W7: =VLOOKUP($M7,Pflanzenkatalog!$A$2:$AB$632,11,FALSE) -> Juli | X7: =VLOOKUP($M7,Pflanzenkatalog!$A$2:$AB$632,12,FALSE) -> 50-80 cm | Y7: =VLOOKUP($M7,Pflanzenkatalog!$A$2:$AB$632,13,FALSE) -> SPAR Bio | Z7: =VLOOKUP($M7,Pflanzenkatalog!$A$2:$AB$632,14,FALSE) -> 0 | AA7: =VLOOKUP($M7,Pflanzenkatalog!$A$2:$AB$632,15,FALSE) -> 0 | AB7: =VLOOKUP($M7,Pflanzenkatalog!$A$2:$AB$632,16,FALSE) -> 0 | AC7: =VLOOKUP($M7,Pflanzenkatalog!$A$2:$AB$632,17,FALSE) -> 0 | AD7: =VLOOKUP($M7,Pflanzenkatalog!$A$2:$AB$632,18,FALSE) -> 0 | AE7: =VLOOKUP($M7,Pflanzenkatalog!$A$2:$AB$632,19,FALSE) -> 0 | AF7: =VLOOKUP($M7,Pflanzenkatalog!$A$2:$AB$632,20,FALSE) -> Frucht
A8: 1UA | B8: Glashaus | C8: Norden/Mauer | D8: Sonne | E8: Niederregal | F8: 1 | G8: unten | H8: A | I8: Stahl 30 | J8: Tomatenhaken | K8: Erde | L8: 1 | M8: 6 | N8: =VLOOKUP($M8,Pflanzenkatalog!$A$2:$AB$632,2,FALSE) -> Cocktailparadeiser Golden Perfection | O8: =VLOOKUP($M8,Pflanzenkatalog!$A$2:$AB$632,3,FALSE) -> 15.03-15.04 | P8: =VLOOKUP($M8,Pflanzenkatalog!$A$2:$AB$632,4,FALSE) -> 20-25 | Q8: =VLOOKUP($M8,Pflanzenkatalog!$A$2:$AB$632,5,FALSE) -> 8-10 | R8: =VLOOKUP($M8,Pflanzenkatalog!$A$2:$AB$632,6,FALSE) -> Licht | S8: =VLOOKUP($M8,Pflanzenkatalog!$A$2:$AB$632,7,FALSE) -> 15.05-31.05. | T8: =VLOOKUP($M8,Pflanzenkatalog!$A$2:$AB$632,8,FALSE) -> nein | U8: =VLOOKUP($M8,Pflanzenkatalog!$A$2:$AB$632,9,FALSE) -> 50 | V8: =VLOOKUP($M8,Pflanzenkatalog!$A$2:$AB$632,10,FALSE) -> 100 | W8: =VLOOKUP($M8,Pflanzenkatalog!$A$2:$AB$632,11,FALSE) -> Juni | X8: =VLOOKUP($M8,Pflanzenkatalog!$A$2:$AB$632,12,FALSE) -> unbegrenzt | Y8: =VLOOKUP($M8,Pflanzenkatalog!$A$2:$AB$632,13,FALSE) -> Arche Noah | Z8: =VLOOKUP($M8,Pflanzenkatalog!$A$2:$AB$632,14,FALSE) -> Buschbohne, Knoblauch, Kohl, Kohlrabi | AA8: =VLOOKUP($M8,Pflanzenkatalog!$A$2:$AB$632,15,FALSE) -> Basilikum, gegen Mehltau und weiße Fliege Tagetes, gegen Nematoden, Viren und weiße Fliege | AB8: =VLOOKUP($M8,Pflanzenkatalog!$A$2:$AB$632,16,FALSE) -> Erbse, Fenchel, Kartoffeln | AC8: =VLOOKUP($M8,Pflanzenkatalog!$A$2:$AB$632,17,FALSE) -> sonniger Standort | AD8: =VLOOKUP($M8,Pflanzenkatalog!$A$2:$AB$632,18,FALSE) -> Goldgelbe Cocktailtomate. Die Früchte sind rund und werden ungefähr 2,5-3cm groß. Im Geschmack sehr süß und aromatisch. Unbegrenzt wachsende Pflanze, entwickelt viele Nebentriebe. Seit 1985 aus Tartu, Estland. | AE8: =VLOOKUP($M8,Pflanzenkatalog!$A$2:$AB$632,19,FALSE) -> 0 | AF8: =VLOOKUP($M8,Pflanzenkatalog!$A$2:$AB$632,20,FALSE) -> Frucht
A9: 1UA | B9: Glashaus | C9: Norden/Mauer | D9: Sonne | E9: Niederregal | F9: 1 | G9: unten | H9: A | I9: Stahl 30 | J9: Tomatenhaken | K9: Erde | L9: 1 | M9: 1 | N9: =VLOOKUP($M9,Pflanzenkatalog!$A$2:$AB$632,2,FALSE) -> Fleischparadeiser Rotes Herz | O9: =VLOOKUP($M9,Pflanzenkatalog!$A$2:$AB$632,3,FALSE) -> 15.03-15.04 | P9: =VLOOKUP($M9,Pflanzenkatalog!$A$2:$AB$632,4,FALSE) -> 20-25 | Q9: =VLOOKUP($M9,Pflanzenkatalog!$A$2:$AB$632,5,FALSE) -> 8-10 | R9: =VLOOKUP($M9,Pflanzenkatalog!$A$2:$AB$632,6,FALSE) -> Licht | S9: =VLOOKUP($M9,Pflanzenkatalog!$A$2:$AB$632,7,FALSE) -> 15.05-31.05. | T9: =VLOOKUP($M9,Pflanzenkatalog!$A$2:$AB$632,8,FALSE) -> nein | U9: =VLOOKUP($M9,Pflanzenkatalog!$A$2:$AB$632,9,FALSE) -> 50 | V9: =VLOOKUP($M9,Pflanzenkatalog!$A$2:$AB$632,10,FALSE) -> 100 | W9: =VLOOKUP($M9,Pflanzenkatalog!$A$2:$AB$632,11,FALSE) -> August | X9: =VLOOKUP($M9,Pflanzenkatalog!$A$2:$AB$632,12,FALSE) -> unbegrenzt, locker belaubt, wirkt im Jugendstadium schwach, bisweilen bräunliche Blätter die später verschwinden | Y9: =VLOOKUP($M9,Pflanzenkatalog!$A$2:$AB$632,13,FALSE) -> Arche Noah | Z9: =VLOOKUP($M9,Pflanzenkatalog!$A$2:$AB$632,14,FALSE) -> Buschbohne, Knoblauch, Kohl, Kohlrabi | AA9: =VLOOKUP($M9,Pflanzenkatalog!$A$2:$AB$632,15,FALSE) -> Basilikum, gegen Mehltau und weiße Fliege Tagetes, gegen Nematoden, Viren und weiße Fliege | AB9: =VLOOKUP($M9,Pflanzenkatalog!$A$2:$AB$632,16,FALSE) -> Erbse, Fenchel, Kartoffeln | AC9: =VLOOKUP($M9,Pflanzenkatalog!$A$2:$AB$632,17,FALSE) -> Ausgeizen, Mulchen, warm, Schutz vor Regen, mäßig von unten gießen | AD9: =VLOOKUP($M9,Pflanzenkatalog!$A$2:$AB$632,18,FALSE) -> Das rotes Ochsenherz lässt sich vielfältig verwenden, für Suppen, Saucen und Salate. Die Ausgewogenheit von Süße und Säure ergibt einen sehr guten Geschmack, herzförmig, schwach gerippt und 10-12 cm groß. Ursprünglich stammt die Sorte aus Kroatien. | AE9: =VLOOKUP($M9,Pflanzenkatalog!$A$2:$AB$632,19,FALSE) -> 0 | AF9: =VLOOKUP($M9,Pflanzenkatalog!$A$2:$AB$632,20,FALSE) -> Frucht
A10: 1UA | B10: Glashaus | C10: Norden/Mauer | D10: Sonne | E10: Niederregal | F10: 1 | G10: unten | H10: A | I10: Stahl 30 | J10: Tomatenhaken | K10: Erde | L10: 1 | M10: 3 | N10: =VLOOKUP($M10,Pflanzenkatalog!$A$2:$AB$632,2,FALSE) -> Basilikum Genoveser | O10: =VLOOKUP($M10,Pflanzenkatalog!$A$2:$AB$632,3,FALSE) -> 01.01.-31.12. | P10: =VLOOKUP($M10,Pflanzenkatalog!$A$2:$AB$632,4,FALSE) -> 18-22 | Q10: =VLOOKUP($M10,Pflanzenkatalog!$A$2:$AB$632,5,FALSE) -> 14-18 | R10: =VLOOKUP($M10,Pflanzenkatalog!$A$2:$AB$632,6,FALSE) -> Licht | S10: =VLOOKUP($M10,Pflanzenkatalog!$A$2:$AB$632,7,FALSE) -> 01.05. | T10: =VLOOKUP($M10,Pflanzenkatalog!$A$2:$AB$632,8,FALSE) -> 31.05.-31.07. | U10: =VLOOKUP($M10,Pflanzenkatalog!$A$2:$AB$632,9,FALSE) -> 30 | V10: =VLOOKUP($M10,Pflanzenkatalog!$A$2:$AB$632,10,FALSE) -> 30 | W10: =VLOOKUP($M10,Pflanzenkatalog!$A$2:$AB$632,11,FALSE) -> Ganzjährig | X10: =VLOOKUP($M10,Pflanzenkatalog!$A$2:$AB$632,12,FALSE) -> Busch bis 50 cm | Y10: =VLOOKUP($M10,Pflanzenkatalog!$A$2:$AB$632,13,FALSE) -> samenmaier Bio | Z10: =VLOOKUP($M10,Pflanzenkatalog!$A$2:$AB$632,14,FALSE) -> Tomaten, Gurken, Kohl gegen Mehltau und weiße Fliege | AA10: =VLOOKUP($M10,Pflanzenkatalog!$A$2:$AB$632,15,FALSE) -> 0 | AB10: =VLOOKUP($M10,Pflanzenkatalog!$A$2:$AB$632,16,FALSE) -> 0 | AC10: =VLOOKUP($M10,Pflanzenkatalog!$A$2:$AB$632,17,FALSE) -> sonniger Standort , durchlässiger Boden | AD10: =VLOOKUP($M10,Pflanzenkatalog!$A$2:$AB$632,18,FALSE) -> Bekommt sie genügend Wärme, wächst sie sehr rasch. | AE10: =VLOOKUP($M10,Pflanzenkatalog!$A$2:$AB$632,19,FALSE) -> 0 | AF10: =VLOOKUP($M10,Pflanzenkatalog!$A$2:$AB$632,20,FALSE) -> Kräuter
A11: 1UB | B11: Glashaus | C11: Norden/Mauer | D11: Sonne | E11: Niederregal | F11: 1 | G11: unten | H11: B | I11: Stahl 20 | J11: nein | K11: Erde | L11: 3 | M11: 4 | N11: =VLOOKUP($M11,Pflanzenkatalog!$A$2:$AB$632,2,FALSE) -> Kohlrabi Superschmelz | O11: =VLOOKUP($M11,Pflanzenkatalog!$A$2:$AB$632,3,FALSE) -> 15.02.-15.03. | P11: =VLOOKUP($M11,Pflanzenkatalog!$A$2:$AB$632,4,FALSE) -> 16-20 | Q11: =VLOOKUP($M11,Pflanzenkatalog!$A$2:$AB$632,5,FALSE) -> 5-8 | R11: =VLOOKUP($M11,Pflanzenkatalog!$A$2:$AB$632,6,FALSE) -> 2 | S11: =VLOOKUP($M11,Pflanzenkatalog!$A$2:$AB$632,7,FALSE) -> 01.04. | T11: =VLOOKUP($M11,Pflanzenkatalog!$A$2:$AB$632,8,FALSE) -> 01.04.-31.05. | U11: =VLOOKUP($M11,Pflanzenkatalog!$A$2:$AB$632,9,FALSE) -> 60 | V11: =VLOOKUP($M11,Pflanzenkatalog!$A$2:$AB$632,10,FALSE) -> 60 | W11: =VLOOKUP($M11,Pflanzenkatalog!$A$2:$AB$632,11,FALSE) -> August | X11: =VLOOKUP($M11,Pflanzenkatalog!$A$2:$AB$632,12,FALSE) -> Riesenkohlrabi, bis zu 8 kg | Y11: =VLOOKUP($M11,Pflanzenkatalog!$A$2:$AB$632,13,FALSE) -> samenmaier Bio | Z11: =VLOOKUP($M11,Pflanzenkatalog!$A$2:$AB$632,14,FALSE) -> Bohnen, Erbsen, Kartoffeln, Kopfsalat, Tomaten, Radieschen, Rote Bete, Sellerie, Spinat, Lauch | AA11: =VLOOKUP($M11,Pflanzenkatalog!$A$2:$AB$632,15,FALSE) -> 0 | AB11: =VLOOKUP($M11,Pflanzenkatalog!$A$2:$AB$632,16,FALSE) -> 0 | AC11: =VLOOKUP($M11,Pflanzenkatalog!$A$2:$AB$632,17,FALSE) -> Frostfrei! Schatten, Knolle kein Erdkontakt wegen Schimmel. Kohlanbaufläche jährlich wechseln! Nährstoffreicher, humosen Boder. Bei Trockenheit regelmäßig gießen, damit die Kohlrabi nicht platzen. Wasser- und Nährstoffmangel führt zu Wachstumsstockungen, mehrmals düngen. | AD11: =VLOOKUP($M11,Pflanzenkatalog!$A$2:$AB$632,18,FALSE) -> Zur Lagerung und zum Tiefgefrieren bestens geeignet. Alle Kohlarten sind von allen Gemüse-Arten am längsten lagerbar und gelten als typisches Wintergemüse. Schon seit der Steinzeit wird vermutet, dass Kohl als Lebensmittel für uns gedient hat. | AE11: =VLOOKUP($M11,Pflanzenkatalog!$A$2:$AB$632,19,FALSE) -> 0 | AF11: =VLOOKUP($M11,Pflanzenkatalog!$A$2:$AB$632,20,FALSE) -> Kohl
A12: 1UC | B12: Glashaus | C12: Norden/Mauer | D12: Sonne | E12: Niederregal | F12: 1 | G12: unten | H12: C | I12: Stahl 20 | J12: nein | K12: Erde | L12: 10 | M12: 41 | N12: =VLOOKUP($M12,Pflanzenkatalog!$A$2:$AB$632,2,FALSE) -> Zwiebel Mix | O12: =VLOOKUP($M12,Pflanzenkatalog!$A$2:$AB$632,3,FALSE) -> 01.02-31.03. | P12: =VLOOKUP($M12,Pflanzenkatalog!$A$2:$AB$632,4,FALSE) -> 10-20 | Q12: =VLOOKUP($M12,Pflanzenkatalog!$A$2:$AB$632,5,FALSE) -> 14-25 | R12: =VLOOKUP($M12,Pflanzenkatalog!$A$2:$AB$632,6,FALSE) -> 1-3 | S12: =VLOOKUP($M12,Pflanzenkatalog!$A$2:$AB$632,7,FALSE) -> 01.04. | T12: =VLOOKUP($M12,Pflanzenkatalog!$A$2:$AB$632,8,FALSE) -> 01.03.-30.04. | U12: =VLOOKUP($M12,Pflanzenkatalog!$A$2:$AB$632,9,FALSE) -> 5 | V12: =VLOOKUP($M12,Pflanzenkatalog!$A$2:$AB$632,10,FALSE) -> 25 | W12: =VLOOKUP($M12,Pflanzenkatalog!$A$2:$AB$632,11,FALSE) -> Mai | X12: =VLOOKUP($M12,Pflanzenkatalog!$A$2:$AB$632,12,FALSE) -> Jungzwiebel Mai/Juni, Knolle August (wenn Laub knickt) | Y12: =VLOOKUP($M12,Pflanzenkatalog!$A$2:$AB$632,13,FALSE) -> unbekannt | Z12: =VLOOKUP($M12,Pflanzenkatalog!$A$2:$AB$632,14,FALSE) -> Bohnenkraut, Erdbeeren, Dill, Kopfsalat, Möhren, Rote Bete | AA12: =VLOOKUP($M12,Pflanzenkatalog!$A$2:$AB$632,15,FALSE) -> 0 | AB12: =VLOOKUP($M12,Pflanzenkatalog!$A$2:$AB$632,16,FALSE) -> Bohnen, Erbsen, Kohl | AC12: =VLOOKUP($M12,Pflanzenkatalog!$A$2:$AB$632,17,FALSE) -> sonnig | AD12: =VLOOKUP($M12,Pflanzenkatalog!$A$2:$AB$632,18,FALSE) -> Jungzwiebel | AE12: =VLOOKUP($M12,Pflanzenkatalog!$A$2:$AB$632,19,FALSE) -> 0 | AF12: =VLOOKUP($M12,Pflanzenkatalog!$A$2:$AB$632,20,FALSE) -> Zwiebel
A13: 1UC | B13: Glashaus | C13: Norden/Mauer | D13: Sonne | E13: Niederregal | F13: 1 | G13: unten | H13: C | I13: Stahl 20 | J13: nein | K13: Erde | L13: 2 | M13: 42 | N13: =VLOOKUP($M13,Pflanzenkatalog!$A$2:$AB$632,2,FALSE) -> Schnittlauch | O13: =VLOOKUP($M13,Pflanzenkatalog!$A$2:$AB$632,3,FALSE) -> 01.02-31.03. | P13: =VLOOKUP($M13,Pflanzenkatalog!$A$2:$AB$632,4,FALSE) -> 18-20 | Q13: =VLOOKUP($M13,Pflanzenkatalog!$A$2:$AB$632,5,FALSE) -> 14-25 | R13: =VLOOKUP($M13,Pflanzenkatalog!$A$2:$AB$632,6,FALSE) -> 0,5-1 | S13: =VLOOKUP($M13,Pflanzenkatalog!$A$2:$AB$632,7,FALSE) -> 01.04. | T13: =VLOOKUP($M13,Pflanzenkatalog!$A$2:$AB$632,8,FALSE) -> 01.03.-30.04. | U13: =VLOOKUP($M13,Pflanzenkatalog!$A$2:$AB$632,9,FALSE) -> 0 | V13: =VLOOKUP($M13,Pflanzenkatalog!$A$2:$AB$632,10,FALSE) -> Streu | W13: =VLOOKUP($M13,Pflanzenkatalog!$A$2:$AB$632,11,FALSE) -> ganzjährig | X13: =VLOOKUP($M13,Pflanzenkatalog!$A$2:$AB$632,12,FALSE) -> 20-50 cm | Y13: =VLOOKUP($M13,Pflanzenkatalog!$A$2:$AB$632,13,FALSE) -> unbekannt | Z13: =VLOOKUP($M13,Pflanzenkatalog!$A$2:$AB$632,14,FALSE) -> Sein Duft vertreibt unter anderem die Möhrenfliege. Schon wenige Horste in der Nachbarschaft reduzieren bei Erdbeeren die Anfälligkeit für Grauschimmel und bei Gurken die Infektionsgefahr mit Falschem Mehltau. | AA13: =VLOOKUP($M13,Pflanzenkatalog!$A$2:$AB$632,15,FALSE) -> 0 | AB13: =VLOOKUP($M13,Pflanzenkatalog!$A$2:$AB$632,16,FALSE) -> Auf dem Beet darf Schnittlauch nicht nach sich selbst und anderen Allium-Arten angebaut werden, zudem verträgt er sich nicht gut mit Kohlgewächsen. | AC13: =VLOOKUP($M13,Pflanzenkatalog!$A$2:$AB$632,17,FALSE) -> Günstig ist ein sonniger bis halbschattiger Platz. Eine Abdeckung mit Vlies beschleunigt bei früher Aussaat das Auflaufen. | AD13: =VLOOKUP($M13,Pflanzenkatalog!$A$2:$AB$632,18,FALSE) -> Eine Direktsaat ist nur auf unkrautfreien Böden empfehlenswert, da die Samen sehr langsam keimen. Bei der Aussaat im Beet wartet man ab, bis der Boden eine Temperatur von fünf Grad Celsius erreicht hat. Wenn Sie die Samen mit grobem Sand mischen, lassen sie sich gleichmäßiger ausstreuen. | AE13: =VLOOKUP($M13,Pflanzenkatalog!$A$2:$AB$632,19,FALSE) -> 0 | AF13: =VLOOKUP($M13,Pflanzenkatalog!$A$2:$AB$632,20,FALSE) -> Kräuter
... A15: 2OA | B15: Glashaus | C15: Norden/Mauer | D15: Sonne | E15: Niederregal | F15: 2 | G15: oben | H15: A | I15: Topf | J15: Tomatenhaken | K15: Erde | L15: 1 | M15: 16 | N15: =VLOOKUP($M15,Pflanzenkatalog!$A$2:$AB$632,2,FALSE) -> Zuckermelone | O15: =VLOOKUP($M15,Pflanzenkatalog!$A$2:$AB$632,3,FALSE) -> 01.04. | P15: =VLOOKUP($M15,Pflanzenkatalog!$A$2:$AB$632,4,FALSE) -> 24 | Q15: =VLOOKUP($M15,Pflanzenkatalog!$A$2:$AB$632,5,FALSE) -> 7-14 | R15: =VLOOKUP($M15,Pflanzenkatalog!$A$2:$AB$632,6,FALSE) -> 0 | S15: =VLOOKUP($M15,Pflanzenkatalog!$A$2:$AB$632,7,FALSE) -> 01.05. | T15: =VLOOKUP($M15,Pflanzenkatalog!$A$2:$AB$632,8,FALSE) -> 01.05. | U15: =VLOOKUP($M15,Pflanzenkatalog!$A$2:$AB$632,9,FALSE) -> 50 | V15: =VLOOKUP($M15,Pflanzenkatalog!$A$2:$AB$632,10,FALSE) -> 100 | W15: =VLOOKUP($M15,Pflanzenkatalog!$A$2:$AB$632,11,FALSE) -> August | X15: =VLOOKUP($M15,Pflanzenkatalog!$A$2:$AB$632,12,FALSE) -> Rankend, Aufbinden | Y15: =VLOOKUP($M15,Pflanzenkatalog!$A$2:$AB$632,13,FALSE) -> own grown | Z15: =VLOOKUP($M15,Pflanzenkatalog!$A$2:$AB$632,14,FALSE) -> 0 | AA15: =VLOOKUP($M15,Pflanzenkatalog!$A$2:$AB$632,15,FALSE) -> 0 | AB15: =VLOOKUP($M15,Pflanzenkatalog!$A$2:$AB$632,16,FALSE) -> 0 | AC15: =VLOOKUP($M15,Pflanzenkatalog!$A$2:$AB$632,17,FALSE) -> Haupttrieb nach dem 4. oder 5. Blatt schneiden, Seitentriebe, nach dem 3.-5. Blatt schneiden. Die daraus entstehenden Seitentriebe bilden die weiblichen, fruchtenden Blüten. Behang pro Pflanze auf 4–6 Stück begrenzen. Im Glashaus manuell befruchten. Kalk, Frost, Windempfindlich | AD15: =VLOOKUP($M15,Pflanzenkatalog!$A$2:$AB$632,18,FALSE) -> Die Charentais liebt sonnige, geschützte Standorte mit warmen, humusreichen Böden. Saftige Melonen aus Ihrem Garten Die Zuckermelone bildet süße, faustgroße Früchte mit hellgrüner, genetzter Schale. Die Erntezeit beginnt im August. | AE15: =VLOOKUP($M15,Pflanzenkatalog!$A$2:$AB$632,19,FALSE) -> 0 | AF15: =VLOOKUP($M15,Pflanzenkatalog!$A$2:$AB$632,20,FALSE) -> Frucht
A16: 2OB | B16: Glashaus | C16: Norden/Mauer | D16: Sonne | E16: Niederregal | F16: 2 | G16: oben | H16: B | I16: Platte | J16: Licht | K16: Erde | M16: Anzucht | N16: =VLOOKUP($M16,Pflanzenkatalog!$A$2:$AB$632,2,FALSE) -> Baby div. | O16: =VLOOKUP($M16,Pflanzenkatalog!$A$2:$AB$632,3,FALSE) -> 0 | P16: =VLOOKUP($M16,Pflanzenkatalog!$A$2:$AB$632,4,FALSE) -> 0 | Q16: =VLOOKUP($M16,Pflanzenkatalog!$A$2:$AB$632,5,FALSE) -> 0 | R16: =VLOOKUP($M16,Pflanzenkatalog!$A$2:$AB$632,6,FALSE) -> 0 | S16: =VLOOKUP($M16,Pflanzenkatalog!$A$2:$AB$632,7,FALSE) -> 0 | T16: =VLOOKUP($M16,Pflanzenkatalog!$A$2:$AB$632,8,FALSE) -> 0 | U16: =VLOOKUP($M16,Pflanzenkatalog!$A$2:$AB$632,9,FALSE) -> 0 | V16: =VLOOKUP($M16,Pflanzenkatalog!$A$2:$AB$632,10,FALSE) -> 0 | W16: =VLOOKUP($M16,Pflanzenkatalog!$A$2:$AB$632,11,FALSE) -> 0 | X16: =VLOOKUP($M16,Pflanzenkatalog!$A$2:$AB$632,12,FALSE) -> 0 | Y16: =VLOOKUP($M16,Pflanzenkatalog!$A$2:$AB$632,13,FALSE) -> 0 | Z16: =VLOOKUP($M16,Pflanzenkatalog!$A$2:$AB$632,14,FALSE) -> 0 | AA16: =VLOOKUP($M16,Pflanzenkatalog!$A$2:$AB$632,15,FALSE) -> 0 | AB16: =VLOOKUP($M16,Pflanzenkatalog!$A$2:$AB$632,16,FALSE) -> 0 | AC16: =VLOOKUP($M16,Pflanzenkatalog!$A$2:$AB$632,17,FALSE) -> 0 | AD16: =VLOOKUP($M16,Pflanzenkatalog!$A$2:$AB$632,18,FALSE) -> 0 | AE16: =VLOOKUP($M16,Pflanzenkatalog!$A$2:$AB$632,19,FALSE) -> 0 | AF16: =VLOOKUP($M16,Pflanzenkatalog!$A$2:$AB$632,20,FALSE) -> 0
A17: 2OC | B17: Glashaus | C17: Norden/Mauer | D17: Sonne | E17: Niederregal | F17: 2 | G17: oben | H17: C | I17: Platte | J17: Licht | K17: Erde | M17: Anzucht | N17: =VLOOKUP($M17,Pflanzenkatalog!$A$2:$AB$632,2,FALSE) -> Baby div. | O17: =VLOOKUP($M17,Pflanzenkatalog!$A$2:$AB$632,3,FALSE) -> 0 | P17: =VLOOKUP($M17,Pflanzenkatalog!$A$2:$AB$632,4,FALSE) -> 0 | Q17: =VLOOKUP($M17,Pflanzenkatalog!$A$2:$AB$632,5,FALSE) -> 0 | R17: =VLOOKUP($M17,Pflanzenkatalog!$A$2:$AB$632,6,FALSE) -> 0 | S17: =VLOOKUP($M17,Pflanzenkatalog!$A$2:$AB$632,7,FALSE) -> 0 | T17: =VLOOKUP($M17,Pflanzenkatalog!$A$2:$AB$632,8,FALSE) -> 0 | U17: =VLOOKUP($M17,Pflanzenkatalog!$A$2:$AB$632,9,FALSE) -> 0 | V17: =VLOOKUP($M17,Pflanzenkatalog!$A$2:$AB$632,10,FALSE) -> 0 | W17: =VLOOKUP($M17,Pflanzenkatalog!$A$2:$AB$632,11,FALSE) -> 0 | X17: =VLOOKUP($M17,Pflanzenkatalog!$A$2:$AB$632,12,FALSE) -> 0 | Y17: =VLOOKUP($M17,Pflanzenkatalog!$A$2:$AB$632,13,FALSE) -> 0 | Z17: =VLOOKUP($M17,Pflanzenkatalog!$A$2:$AB$632,14,FALSE) -> 0 | AA17: =VLOOKUP($M17,Pflanzenkatalog!$A$2:$AB$632,15,FALSE) -> 0 | AB17: =VLOOKUP($M17,Pflanzenkatalog!$A$2:$AB$632,16,FALSE) -> 0 | AC17: =VLOOKUP($M17,Pflanzenkatalog!$A$2:$AB$632,17,FALSE) -> 0 | AD17: =VLOOKUP($M17,Pflanzenkatalog!$A$2:$AB$632,18,FALSE) -> 0 | AE17: =VLOOKUP($M17,Pflanzenkatalog!$A$2:$AB$632,19,FALSE) -> 0 | AF17: =VLOOKUP($M17,Pflanzenkatalog!$A$2:$AB$632,20,FALSE) -> 0
A18: 2UA | B18: Glashaus | C18: Norden/Mauer | D18: Sonne | E18: Niederregal | F18: 2 | G18: unten | H18: A | I18: Stahl 30 | J18: Tomatenhaken | K18: Erde | L18: 1 | M18: 2 | N18: =VLOOKUP($M18,Pflanzenkatalog!$A$2:$AB$632,2,FALSE) -> Salatparadeiser Quedlinburger Frühe Liebe | O18: =VLOOKUP($M18,Pflanzenkatalog!$A$2:$AB$632,3,FALSE) -> 15.03-15.04 | P18: =VLOOKUP($M18,Pflanzenkatalog!$A$2:$AB$632,4,FALSE) -> 20-25 | Q18: =VLOOKUP($M18,Pflanzenkatalog!$A$2:$AB$632,5,FALSE) -> 8-10 | R18: =VLOOKUP($M18,Pflanzenkatalog!$A$2:$AB$632,6,FALSE) -> Licht | S18: =VLOOKUP($M18,Pflanzenkatalog!$A$2:$AB$632,7,FALSE) -> 15.05-31.05. | T18: =VLOOKUP($M18,Pflanzenkatalog!$A$2:$AB$632,8,FALSE) -> nein | U18: =VLOOKUP($M18,Pflanzenkatalog!$A$2:$AB$632,9,FALSE) -> 50 | V18: =VLOOKUP($M18,Pflanzenkatalog!$A$2:$AB$632,10,FALSE) -> 80 | W18: =VLOOKUP($M18,Pflanzenkatalog!$A$2:$AB$632,11,FALSE) -> Juli | X18: =VLOOKUP($M18,Pflanzenkatalog!$A$2:$AB$632,12,FALSE) -> Stabtomate wächst bis 1,2 m hoch und hat kartoffelblättriges lockeres Laub | Y18: =VLOOKUP($M18,Pflanzenkatalog!$A$2:$AB$632,13,FALSE) -> Arche Noah | Z18: =VLOOKUP($M18,Pflanzenkatalog!$A$2:$AB$632,14,FALSE) -> Buschbohne, Knoblauch, Kohl, Kohlrabi | AA18: =VLOOKUP($M18,Pflanzenkatalog!$A$2:$AB$632,15,FALSE) -> Basilikum, gegen Mehltau und weiße Fliege Tagetes, gegen Nematoden, Viren und weiße Fliege | AB18: =VLOOKUP($M18,Pflanzenkatalog!$A$2:$AB$632,16,FALSE) -> Erbse, Fenchel, Kartoffeln | AC18: =VLOOKUP($M18,Pflanzenkatalog!$A$2:$AB$632,17,FALSE) -> nicht ausgeizen, Mulchen, warm, Schutz vor Regen, mäßig von unten gießen | AD18: =VLOOKUP($M18,Pflanzenkatalog!$A$2:$AB$632,18,FALSE) -> Im Salat kommt der süß-aromatische Geschmack hervorragend zur Geltung. Extrem frühreifend ist die Sorte auch für rauhere Lagen empfehlenswert. Die roten, runden, ca. 4 cm großen Früchte kann man die ganze Saison über ernten. | AE18: =VLOOKUP($M18,Pflanzenkatalog!$A$2:$AB$632,19,FALSE) -> 0 | AF18: =VLOOKUP($M18,Pflanzenkatalog!$A$2:$AB$632,20,FALSE) -> Frucht
A19: 2UA | B19: Glashaus | C19: Norden/Mauer | D19: Sonne | E19: Niederregal | F19: 2 | G19: unten | H19: A | I19: Stahl 30 | J19: Tomatenhaken | K19: Erde | L19: 1 | M19: 49 | N19: =VLOOKUP($M19,Pflanzenkatalog!$A$2:$AB$632,2,FALSE) -> Paradeiser Ochsenherz Tschernij Prinz | O19: =VLOOKUP($M19,Pflanzenkatalog!$A$2:$AB$632,3,FALSE) -> 01.02-31.03. | P19: =VLOOKUP($M19,Pflanzenkatalog!$A$2:$AB$632,4,FALSE) -> 20-25 | Q19: =VLOOKUP($M19,Pflanzenkatalog!$A$2:$AB$632,5,FALSE) -> 8-10 | R19: =VLOOKUP($M19,Pflanzenkatalog!$A$2:$AB$632,6,FALSE) -> 0,5-1 | S19: =VLOOKUP($M19,Pflanzenkatalog!$A$2:$AB$632,7,FALSE) -> 15.04.-15.05. | T19: =VLOOKUP($M19,Pflanzenkatalog!$A$2:$AB$632,8,FALSE) -> 15.05-31.05. | U19: =VLOOKUP($M19,Pflanzenkatalog!$A$2:$AB$632,9,FALSE) -> 50 | V19: =VLOOKUP($M19,Pflanzenkatalog!$A$2:$AB$632,10,FALSE) -> 60 | W19: =VLOOKUP($M19,Pflanzenkatalog!$A$2:$AB$632,11,FALSE) -> Juli | X19: =VLOOKUP($M19,Pflanzenkatalog!$A$2:$AB$632,12,FALSE) -> Stabtomate | Y19: =VLOOKUP($M19,Pflanzenkatalog!$A$2:$AB$632,13,FALSE) -> REINSAAT | Z19: =VLOOKUP($M19,Pflanzenkatalog!$A$2:$AB$632,14,FALSE) -> Buschbohne, Knoblauch, Kohl, Kohlrabi | AA19: =VLOOKUP($M19,Pflanzenkatalog!$A$2:$AB$632,15,FALSE) -> Basilikum, gegen Mehltau und weiße Fliege Tagetes, gegen Nematoden, Viren und weiße Fliege | AB19: =VLOOKUP($M19,Pflanzenkatalog!$A$2:$AB$632,16,FALSE) -> Erbse, Fenchel, Kartoffeln | AC19: =VLOOKUP($M19,Pflanzenkatalog!$A$2:$AB$632,17,FALSE) -> 0 | AD19: =VLOOKUP($M19,Pflanzenkatalog!$A$2:$AB$632,18,FALSE) -> Halbdeterminante Fleischtomate aus der EHZ von ReinSaat. Die braunroten, flachrunden Früchte sind von herausragend gutem Geschmack. Mehrkammerige, fleischige und sehr saftige Früchte mit einem Fruchtgewicht von ca. 200 – 300 g. Früh einsetzende Ernte. Sehr beliebte Hausgärtnersorte. | AE19: =VLOOKUP($M19,Pflanzenkatalog!$A$2:$AB$632,19,FALSE) -> 0 | AF19: =VLOOKUP($M19,Pflanzenkatalog!$A$2:$AB$632,20,FALSE) -> Frucht
A20: 2UB | B20: Glashaus | C20: Norden/Mauer | D20: Sonne | E20: Niederregal | F20: 2 | G20: unten | H20: B | I20: Platte | J20: nein | K20: trocken | M20: Lager | N20: =VLOOKUP($M20,Pflanzenkatalog!$A$2:$AB$632,2,FALSE) -> Lagerfläche | O20: =VLOOKUP($M20,Pflanzenkatalog!$A$2:$AB$632,3,FALSE) -> 0 | P20: =VLOOKUP($M20,Pflanzenkatalog!$A$2:$AB$632,4,FALSE) -> 0 | Q20: =VLOOKUP($M20,Pflanzenkatalog!$A$2:$AB$632,5,FALSE) -> 0 | R20: =VLOOKUP($M20,Pflanzenkatalog!$A$2:$AB$632,6,FALSE) -> 0 | S20: =VLOOKUP($M20,Pflanzenkatalog!$A$2:$AB$632,7,FALSE) -> 0 | T20: =VLOOKUP($M20,Pflanzenkatalog!$A$2:$AB$632,8,FALSE) -> 0 | U20: =VLOOKUP($M20,Pflanzenkatalog!$A$2:$AB$632,9,FALSE) -> 0 | V20: =VLOOKUP($M20,Pflanzenkatalog!$A$2:$AB$632,10,FALSE) -> 0 | W20: =VLOOKUP($M20,Pflanzenkatalog!$A$2:$AB$632,11,FALSE) -> 0 | X20: =VLOOKUP($M20,Pflanzenkatalog!$A$2:$AB$632,12,FALSE) -> 0 | Y20: =VLOOKUP($M20,Pflanzenkatalog!$A$2:$AB$632,13,FALSE) -> 0 | Z20: =VLOOKUP($M20,Pflanzenkatalog!$A$2:$AB$632,14,FALSE) -> 0 | AA20: =VLOOKUP($M20,Pflanzenkatalog!$A$2:$AB$632,15,FALSE) -> 0 | AB20: =VLOOKUP($M20,Pflanzenkatalog!$A$2:$AB$632,16,FALSE) -> 0 | AC20: =VLOOKUP($M20,Pflanzenkatalog!$A$2:$AB$632,17,FALSE) -> 0 | AD20: =VLOOKUP($M20,Pflanzenkatalog!$A$2:$AB$632,18,FALSE) -> 0 | AE20: =VLOOKUP($M20,Pflanzenkatalog!$A$2:$AB$632,19,FALSE) -> 0 | AF20: =VLOOKUP($M20,Pflanzenkatalog!$A$2:$AB$632,20,FALSE) -> 0
A21: 2UC | B21: Glashaus | C21: Norden/Mauer | D21: Sonne | E21: Niederregal | F21: 2 | G21: unten | H21: C | I21: Platte | J21: nein | K21: trocken | M21: Lager | N21: =VLOOKUP($M21,Pflanzenkatalog!$A$2:$AB$632,2,FALSE) -> Lagerfläche | O21: =VLOOKUP($M21,Pflanzenkatalog!$A$2:$AB$632,3,FALSE) -> 0 | P21: =VLOOKUP($M21,Pflanzenkatalog!$A$2:$AB$632,4,FALSE) -> 0 | Q21: =VLOOKUP($M21,Pflanzenkatalog!$A$2:$AB$632,5,FALSE) -> 0 | R21: =VLOOKUP($M21,Pflanzenkatalog!$A$2:$AB$632,6,FALSE) -> 0 | S21: =VLOOKUP($M21,Pflanzenkatalog!$A$2:$AB$632,7,FALSE) -> 0 | T21: =VLOOKUP($M21,Pflanzenkatalog!$A$2:$AB$632,8,FALSE) -> 0 | U21: =VLOOKUP($M21,Pflanzenkatalog!$A$2:$AB$632,9,FALSE) -> 0 | V21: =VLOOKUP($M21,Pflanzenkatalog!$A$2:$AB$632,10,FALSE) -> 0 | W21: =VLOOKUP($M21,Pflanzenkatalog!$A$2:$AB$632,11,FALSE) -> 0 | X21: =VLOOKUP($M21,Pflanzenkatalog!$A$2:$AB$632,12,FALSE) -> 0 | Y21: =VLOOKUP($M21,Pflanzenkatalog!$A$2:$AB$632,13,FALSE) -> 0 | Z21: =VLOOKUP($M21,Pflanzenkatalog!$A$2:$AB$632,14,FALSE) -> 0 | AA21: =VLOOKUP($M21,Pflanzenkatalog!$A$2:$AB$632,15,FALSE) -> 0 | AB21: =VLOOKUP($M21,Pflanzenkatalog!$A$2:$AB$632,16,FALSE) -> 0 | AC21: =VLOOKUP($M21,Pflanzenkatalog!$A$2:$AB$632,17,FALSE) -> 0 | AD21: =VLOOKUP($M21,Pflanzenkatalog!$A$2:$AB$632,18,FALSE) -> 0 | AE21: =VLOOKUP($M21,Pflanzenkatalog!$A$2:$AB$632,19,FALSE) -> 0 | AF21: =VLOOKUP($M21,Pflanzenkatalog!$A$2:$AB$632,20,FALSE) -> 0
A22: 3OA | B22: Glashaus | C22: Norden/Mauer | D22: Sonne | E22: Niederregal | F22: 3 | G22: oben | H22: A | I22: Stahl 20 | J22: Stäbe | K22: Erde | L22: 2 | M22: 14 | N22: =VLOOKUP($M22,Pflanzenkatalog!$A$2:$AB$632,2,FALSE) -> Chili Lemon Drop | O22: =VLOOKUP($M22,Pflanzenkatalog!$A$2:$AB$632,3,FALSE) -> 01.03. | P22: =VLOOKUP($M22,Pflanzenkatalog!$A$2:$AB$632,4,FALSE) -> 25-30 | Q22: =VLOOKUP($M22,Pflanzenkatalog!$A$2:$AB$632,5,FALSE) -> 10-14 | R22: =VLOOKUP($M22,Pflanzenkatalog!$A$2:$AB$632,6,FALSE) -> 1 | S22: =VLOOKUP($M22,Pflanzenkatalog!$A$2:$AB$632,7,FALSE) -> 01.05. | T22: =VLOOKUP($M22,Pflanzenkatalog!$A$2:$AB$632,8,FALSE) -> nein | U22: =VLOOKUP($M22,Pflanzenkatalog!$A$2:$AB$632,9,FALSE) -> 40 | V22: =VLOOKUP($M22,Pflanzenkatalog!$A$2:$AB$632,10,FALSE) -> 40 | W22: =VLOOKUP($M22,Pflanzenkatalog!$A$2:$AB$632,11,FALSE) -> August | X22: =VLOOKUP($M22,Pflanzenkatalog!$A$2:$AB$632,12,FALSE) -> 80 cm, Anstäben | Y22: =VLOOKUP($M22,Pflanzenkatalog!$A$2:$AB$632,13,FALSE) -> samen greisslerei | Z22: =VLOOKUP($M22,Pflanzenkatalog!$A$2:$AB$632,14,FALSE) -> Rucola, Radieschen, Pertersilie, Basilikum | AA22: =VLOOKUP($M22,Pflanzenkatalog!$A$2:$AB$632,15,FALSE) -> 0 | AB22: =VLOOKUP($M22,Pflanzenkatalog!$A$2:$AB$632,16,FALSE) -> 0 | AC22: =VLOOKUP($M22,Pflanzenkatalog!$A$2:$AB$632,17,FALSE) -> mehrjährig! Jungpflanzen wachsen langsam, vor Frost schützen, langsam abhärten, feuchtes, lockeres und nährstoffreichen Substrat, Boden im Idealfall einen neutralen bis leicht sauren pH-Wert, mit Kompost düngen | AD22: =VLOOKUP($M22,Pflanzenkatalog!$A$2:$AB$632,18,FALSE) -> Diese Sorte hat dünnwandige, leuchtend gelbe Schoten, die eine ausgesprochene Schärfe aufweisen (Schärfegrad 7 – 8). Zusätzlich besitzen sie ein typisches Zitronenaroma. Die Pflanze erreicht im Freiland bis 80 cm Wuchshöhe. Sie ist mehrjährig, aber nicht frosthart! Nutzung: Chilischoten zum Würzen frisch oder getrocknet. Daraus läßt sich ein farblich sehr schönes Chilipulver mahlen. | AE22: =VLOOKUP($M22,Pflanzenkatalog!$A$2:$AB$632,19,FALSE) -> 0 | AF22: =VLOOKUP($M22,Pflanzenkatalog!$A$2:$AB$632,20,FALSE) -> Frucht
A23: 3OA | B23: Glashaus | C23: Norden/Mauer | D23: Sonne | E23: Niederregal | F23: 3 | G23: oben | H23: A | I23: Stahl 20 | J23: Stäbe | K23: Erde | L23: 2 | M23: 51 | N23: =VLOOKUP($M23,Pflanzenkatalog!$A$2:$AB$632,2,FALSE) -> Chili Diavoletto | O23: =VLOOKUP($M23,Pflanzenkatalog!$A$2:$AB$632,3,FALSE) -> 15.02.-15.03. | P23: =VLOOKUP($M23,Pflanzenkatalog!$A$2:$AB$632,4,FALSE) -> 20-25 | Q23: =VLOOKUP($M23,Pflanzenkatalog!$A$2:$AB$632,5,FALSE) -> 10-14 | R23: =VLOOKUP($M23,Pflanzenkatalog!$A$2:$AB$632,6,FALSE) -> 1 | S23: =VLOOKUP($M23,Pflanzenkatalog!$A$2:$AB$632,7,FALSE) -> 15.04.-30.04. | T23: =VLOOKUP($M23,Pflanzenkatalog!$A$2:$AB$632,8,FALSE) -> nein | U23: =VLOOKUP($M23,Pflanzenkatalog!$A$2:$AB$632,9,FALSE) -> 50 | V23: =VLOOKUP($M23,Pflanzenkatalog!$A$2:$AB$632,10,FALSE) -> 70 | W23: =VLOOKUP($M23,Pflanzenkatalog!$A$2:$AB$632,11,FALSE) -> Juli | X23: =VLOOKUP($M23,Pflanzenkatalog!$A$2:$AB$632,12,FALSE) -> 50-80 cm | Y23: =VLOOKUP($M23,Pflanzenkatalog!$A$2:$AB$632,13,FALSE) -> REINSAAT | Z23: =VLOOKUP($M23,Pflanzenkatalog!$A$2:$AB$632,14,FALSE) -> Rucola, Radieschen, Pertersilie, Basilikum | AA23: =VLOOKUP($M23,Pflanzenkatalog!$A$2:$AB$632,15,FALSE) -> 0 | AB23: =VLOOKUP($M23,Pflanzenkatalog!$A$2:$AB$632,16,FALSE) -> 0 | AC23: =VLOOKUP($M23,Pflanzenkatalog!$A$2:$AB$632,17,FALSE) -> mehrjährig! Jungpflanzen wachsen langsam, vor Frost schützen, langsam abhärten, feuchtes, lockeres und nährstoffreichen Substrat, Boden im Idealfall einen neutralen bis leicht sauren pH-Wert, mit Kompost düngen | AD23: =VLOOKUP($M23,Pflanzenkatalog!$A$2:$AB$632,18,FALSE) -> Züchtung ReinSaat. Dekorativer, langgestreckter, fleischiger Chili mit attraktiven lilafarbenen Blüten, Stielen, Kelchen und Blattadern. Die Früchte reifen von lila auf goldbraun zu orangerot ab. Gut geeignet zum Frischverzehr, in Salsas oder zum Einlegen. Für Gewächshaus und geschützte Freilandlagen. Schärfegrad 6 – 7 | AE23: =VLOOKUP($M23,Pflanzenkatalog!$A$2:$AB$632,19,FALSE) -> 0 | AF23: =VLOOKUP($M23,Pflanzenkatalog!$A$2:$AB$632,20,FALSE) -> Frucht
A24: 3OB | B24: Glashaus | C24: Norden/Mauer | D24: Sonne | E24: Niederregal | F24: 3 | G24: oben | H24: B | I24: Stahl 20 | J24: nein | K24: Erde | L24: 2 | M24: 18 | N24: =VLOOKUP($M24,Pflanzenkatalog!$A$2:$AB$632,2,FALSE) -> Paprika spitz rot | O24: =VLOOKUP($M24,Pflanzenkatalog!$A$2:$AB$632,3,FALSE) -> 01.02.-15.04. | P24: =VLOOKUP($M24,Pflanzenkatalog!$A$2:$AB$632,4,FALSE) -> 22-25 | Q24: =VLOOKUP($M24,Pflanzenkatalog!$A$2:$AB$632,5,FALSE) -> 10-14 | R24: =VLOOKUP($M24,Pflanzenkatalog!$A$2:$AB$632,6,FALSE) -> 0,5-1 | S24: =VLOOKUP($M24,Pflanzenkatalog!$A$2:$AB$632,7,FALSE) -> 01.04.-01.06. | T24: =VLOOKUP($M24,Pflanzenkatalog!$A$2:$AB$632,8,FALSE) -> nein | U24: =VLOOKUP($M24,Pflanzenkatalog!$A$2:$AB$632,9,FALSE) -> 60 | V24: =VLOOKUP($M24,Pflanzenkatalog!$A$2:$AB$632,10,FALSE) -> 80 | W24: =VLOOKUP($M24,Pflanzenkatalog!$A$2:$AB$632,11,FALSE) -> Juli | X24: =VLOOKUP($M24,Pflanzenkatalog!$A$2:$AB$632,12,FALSE) -> 50-80 cm | Y24: =VLOOKUP($M24,Pflanzenkatalog!$A$2:$AB$632,13,FALSE) -> SPAR Bio | Z24: =VLOOKUP($M24,Pflanzenkatalog!$A$2:$AB$632,14,FALSE) -> 0 | AA24: =VLOOKUP($M24,Pflanzenkatalog!$A$2:$AB$632,15,FALSE) -> 0 | AB24: =VLOOKUP($M24,Pflanzenkatalog!$A$2:$AB$632,16,FALSE) -> 0 | AC24: =VLOOKUP($M24,Pflanzenkatalog!$A$2:$AB$632,17,FALSE) -> 0 | AD24: =VLOOKUP($M24,Pflanzenkatalog!$A$2:$AB$632,18,FALSE) -> 0 | AE24: =VLOOKUP($M24,Pflanzenkatalog!$A$2:$AB$632,19,FALSE) -> 0 | AF24: =VLOOKUP($M24,Pflanzenkatalog!$A$2:$AB$632,20,FALSE) -> Frucht
A25: 3OB | B25: Glashaus | C25: Norden/Mauer | D25: Sonne | E25: Niederregal | F25: 3 | G25: oben | H25: B | I25: Stahl 20 | J25: nein | K25: Erde | L25: 2 | M25: 50 | N25: =VLOOKUP($M25,Pflanzenkatalog!$A$2:$AB$632,2,FALSE) -> Paprika Snack Hamik | O25: =VLOOKUP($M25,Pflanzenkatalog!$A$2:$AB$632,3,FALSE) -> 15.01.-31.03. | P25: =VLOOKUP($M25,Pflanzenkatalog!$A$2:$AB$632,4,FALSE) -> 20-25 | Q25: =VLOOKUP($M25,Pflanzenkatalog!$A$2:$AB$632,5,FALSE) -> 14-21 | R25: =VLOOKUP($M25,Pflanzenkatalog!$A$2:$AB$632,6,FALSE) -> 0,5-1 | S25: =VLOOKUP($M25,Pflanzenkatalog!$A$2:$AB$632,7,FALSE) -> 15.04.-30.04. | T25: =VLOOKUP($M25,Pflanzenkatalog!$A$2:$AB$632,8,FALSE) -> 15.05.-15.06. | U25: =VLOOKUP($M25,Pflanzenkatalog!$A$2:$AB$632,9,FALSE) -> 50 | V25: =VLOOKUP($M25,Pflanzenkatalog!$A$2:$AB$632,10,FALSE) -> 70 | W25: =VLOOKUP($M25,Pflanzenkatalog!$A$2:$AB$632,11,FALSE) -> Juli | X25: =VLOOKUP($M25,Pflanzenkatalog!$A$2:$AB$632,12,FALSE) -> 20-50 cm | Y25: =VLOOKUP($M25,Pflanzenkatalog!$A$2:$AB$632,13,FALSE) -> REINSAAT | Z25: =VLOOKUP($M25,Pflanzenkatalog!$A$2:$AB$632,14,FALSE) -> Salat | AA25: =VLOOKUP($M25,Pflanzenkatalog!$A$2:$AB$632,15,FALSE) -> Tagetes gegen Nematoden, Viren und weiße Fliege | AB25: =VLOOKUP($M25,Pflanzenkatalog!$A$2:$AB$632,16,FALSE) -> 0 | AC25: =VLOOKUP($M25,Pflanzenkatalog!$A$2:$AB$632,17,FALSE) -> 0 | AD25: =VLOOKUP($M25,Pflanzenkatalog!$A$2:$AB$632,18,FALSE) -> 0 | AE25: =VLOOKUP($M25,Pflanzenkatalog!$A$2:$AB$632,19,FALSE) -> 0 | AF25: =VLOOKUP($M25,Pflanzenkatalog!$A$2:$AB$632,20,FALSE) -> Frucht
A26: 3OC | B26: Glashaus | C26: Norden/Mauer | D26: Sonne | E26: Niederregal | F26: 3 | G26: oben | H26: C | I26: Stahl 30 | J26: Gitter | K26: Erde | L26: 10 | M26: 8 | N26: =VLOOKUP($M26,Pflanzenkatalog!$A$2:$AB$632,2,FALSE) -> Knackerbse Spring Blush | O26: =VLOOKUP($M26,Pflanzenkatalog!$A$2:$AB$632,3,FALSE) -> 01.03.-31.05. | P26: =VLOOKUP($M26,Pflanzenkatalog!$A$2:$AB$632,4,FALSE) -> 10-20 | Q26: =VLOOKUP($M26,Pflanzenkatalog!$A$2:$AB$632,5,FALSE) -> 8-14 | R26: =VLOOKUP($M26,Pflanzenkatalog!$A$2:$AB$632,6,FALSE) -> 3 | S26: =VLOOKUP($M26,Pflanzenkatalog!$A$2:$AB$632,7,FALSE) -> 0 | T26: =VLOOKUP($M26,Pflanzenkatalog!$A$2:$AB$632,8,FALSE) -> 01.03.-31.05. | U26: =VLOOKUP($M26,Pflanzenkatalog!$A$2:$AB$632,9,FALSE) -> 3 | V26: =VLOOKUP($M26,Pflanzenkatalog!$A$2:$AB$632,10,FALSE) -> 30 | W26: =VLOOKUP($M26,Pflanzenkatalog!$A$2:$AB$632,11,FALSE) -> Mai | X26: =VLOOKUP($M26,Pflanzenkatalog!$A$2:$AB$632,12,FALSE) -> ca. bis 120 cm, Rankhilfe | Y26: =VLOOKUP($M26,Pflanzenkatalog!$A$2:$AB$632,13,FALSE) -> Sorten WERKSTATT | Z26: =VLOOKUP($M26,Pflanzenkatalog!$A$2:$AB$632,14,FALSE) -> Dill, Fenchel, Gurken, Kohlarten, Mais, Möhren, Kohlrabi, Kopfsalat, Radieschen, Zucchini | AA26: =VLOOKUP($M26,Pflanzenkatalog!$A$2:$AB$632,15,FALSE) -> 0 | AB26: =VLOOKUP($M26,Pflanzenkatalog!$A$2:$AB$632,16,FALSE) -> Bohnen, Kartoffeln, Knoblauch, Lauch, Tomaten, Zwiebeln | AC26: =VLOOKUP($M26,Pflanzenkatalog!$A$2:$AB$632,17,FALSE) -> Halbschatten, Erbsen nicht zu spät aussäen Die meisten Erbsensorten bilden an kühlen, kurzen Tagen nur Blätter. Erst wenn die Tage länger werden und die Temperaturen steigen, meist ab Mitte Mai, entwickeln sich Blüten. Wer viel ernten möchte, sät die Erbsen so früh wie möglich, damit die Pflanzen vor der Blütenbildung noch lange wachsen, empfehlenswert ist es, die Erbsen spätestens Ende April zu säen. | AD26: =VLOOKUP($M26,Pflanzenkatalog!$A$2:$AB$632,18,FALSE) -> Knackerbse, das heißt, die Hülsen sind sehr knackig und süß, nicht fädig und somit lang beerntbar. Nicht vergleichbar mit Zuckererbsen! Diese neue Sorte hat grün-violetten Schoten, ist aber noch nicht ganz einheitlich durchselektiert. Nutzbar sind die Schoten (frisch und gekocht), die frischen Erbsensamen und die Ranken, von denen die Pflanze zahlreiche bildet. Sehr schön! Aussaat ab März. Direktsaat. Rankhilfe notwenig. | AE26: =VLOOKUP($M26,Pflanzenkatalog!$A$2:$AB$632,19,FALSE) -> 0 | AF26: =VLOOKUP($M26,Pflanzenkatalog!$A$2:$AB$632,20,FALSE) -> Hülse
A27: 3UA | B27: Glashaus | C27: Norden/Mauer | D27: Sonne | E27: Niederregal | F27: 3 | G27: unten | H27: A | I27: Stahl 30 | J27: Tomatenhaken | K27: Erde | L27: 1 | M27: 1 | N27: =VLOOKUP($M27,Pflanzenkatalog!$A$2:$AB$632,2,FALSE) -> Fleischparadeiser Rotes Herz | O27: =VLOOKUP($M27,Pflanzenkatalog!$A$2:$AB$632,3,FALSE) -> 15.03-15.04 | P27: =VLOOKUP($M27,Pflanzenkatalog!$A$2:$AB$632,4,FALSE) -> 20-25 | Q27: =VLOOKUP($M27,Pflanzenkatalog!$A$2:$AB$632,5,FALSE) -> 8-10 | R27: =VLOOKUP($M27,Pflanzenkatalog!$A$2:$AB$632,6,FALSE) -> Licht | S27: =VLOOKUP($M27,Pflanzenkatalog!$A$2:$AB$632,7,FALSE) -> 15.05-31.05. | T27: =VLOOKUP($M27,Pflanzenkatalog!$A$2:$AB$632,8,FALSE) -> nein | U27: =VLOOKUP($M27,Pflanzenkatalog!$A$2:$AB$632,9,FALSE) -> 50 | V27: =VLOOKUP($M27,Pflanzenkatalog!$A$2:$AB$632,10,FALSE) -> 100 | W27: =VLOOKUP($M27,Pflanzenkatalog!$A$2:$AB$632,11,FALSE) -> August | X27: =VLOOKUP($M27,Pflanzenkatalog!$A$2:$AB$632,12,FALSE) -> unbegrenzt, locker belaubt, wirkt im Jugendstadium schwach, bisweilen bräunliche Blätter die später verschwinden | Y27: =VLOOKUP($M27,Pflanzenkatalog!$A$2:$AB$632,13,FALSE) -> Arche Noah | Z27: =VLOOKUP($M27,Pflanzenkatalog!$A$2:$AB$632,14,FALSE) -> Buschbohne, Knoblauch, Kohl, Kohlrabi | AA27: =VLOOKUP($M27,Pflanzenkatalog!$A$2:$AB$632,15,FALSE) -> Basilikum, gegen Mehltau und weiße Fliege Tagetes, gegen Nematoden, Viren und weiße Fliege | AB27: =VLOOKUP($M27,Pflanzenkatalog!$A$2:$AB$632,16,FALSE) -> Erbse, Fenchel, Kartoffeln | AC27: =VLOOKUP($M27,Pflanzenkatalog!$A$2:$AB$632,17,FALSE) -> Ausgeizen, Mulchen, warm, Schutz vor Regen, mäßig von unten gießen | AD27: =VLOOKUP($M27,Pflanzenkatalog!$A$2:$AB$632,18,FALSE) -> Das rotes Ochsenherz lässt sich vielfältig verwenden, für Suppen, Saucen und Salate. Die Ausgewogenheit von Süße und Säure ergibt einen sehr guten Geschmack, herzförmig, schwach gerippt und 10-12 cm groß. Ursprünglich stammt die Sorte aus Kroatien. | AE27: =VLOOKUP($M27,Pflanzenkatalog!$A$2:$AB$632,19,FALSE) -> 0 | AF27: =VLOOKUP($M27,Pflanzenkatalog!$A$2:$AB$632,20,FALSE) -> Frucht
A28: 3UA | B28: Glashaus | C28: Norden/Mauer | D28: Sonne | E28: Niederregal | F28: 3 | G28: unten | H28: A | I28: Stahl 30 | J28: Tomatenhaken | K28: Erde | L28: 1 | M28: 48 | N28: =VLOOKUP($M28,Pflanzenkatalog!$A$2:$AB$632,2,FALSE) -> Salatparadeiser gestreift SPAR | O28: =VLOOKUP($M28,Pflanzenkatalog!$A$2:$AB$632,3,FALSE) -> 15.03-15.04. | P28: =VLOOKUP($M28,Pflanzenkatalog!$A$2:$AB$632,4,FALSE) -> 20-25 | Q28: =VLOOKUP($M28,Pflanzenkatalog!$A$2:$AB$632,5,FALSE) -> 8-10 | R28: =VLOOKUP($M28,Pflanzenkatalog!$A$2:$AB$632,6,FALSE) -> Licht | S28: =VLOOKUP($M28,Pflanzenkatalog!$A$2:$AB$632,7,FALSE) -> 15.05-31.05. | T28: =VLOOKUP($M28,Pflanzenkatalog!$A$2:$AB$632,8,FALSE) -> nein | U28: =VLOOKUP($M28,Pflanzenkatalog!$A$2:$AB$632,9,FALSE) -> 50 | V28: =VLOOKUP($M28,Pflanzenkatalog!$A$2:$AB$632,10,FALSE) -> 80 | W28: =VLOOKUP($M28,Pflanzenkatalog!$A$2:$AB$632,11,FALSE) -> Juli | X28: =VLOOKUP($M28,Pflanzenkatalog!$A$2:$AB$632,12,FALSE) -> Stabtomate | Y28: =VLOOKUP($M28,Pflanzenkatalog!$A$2:$AB$632,13,FALSE) -> SPAR Bio | Z28: =VLOOKUP($M28,Pflanzenkatalog!$A$2:$AB$632,14,FALSE) -> Buschbohne, Knoblauch, Kohl, Kohlrabi | AA28: =VLOOKUP($M28,Pflanzenkatalog!$A$2:$AB$632,15,FALSE) -> Basilikum, gegen Mehltau und weiße Fliege Tagetes, gegen Nematoden, Viren und weiße Fliege | AB28: =VLOOKUP($M28,Pflanzenkatalog!$A$2:$AB$632,16,FALSE) -> Erbse, Fenchel, Kartoffeln | AC28: =VLOOKUP($M28,Pflanzenkatalog!$A$2:$AB$632,17,FALSE) -> 0 | AD28: =VLOOKUP($M28,Pflanzenkatalog!$A$2:$AB$632,18,FALSE) -> Im Salat kommt der süß-aromatische Geschmack hervorragend zur Geltung. Extrem frühreifend ist die Sorte auch für rauhere Lagen empfehlenswert. Die roten, runden, ca. 4 cm großen Früchte kann man die ganze Saison über ernten. | AE28: =VLOOKUP($M28,Pflanzenkatalog!$A$2:$AB$632,19,FALSE) -> 0 | AF28: =VLOOKUP($M28,Pflanzenkatalog!$A$2:$AB$632,20,FALSE) -> Frucht
